[2022-01-28 07:15:05,708] {processor.py:163} INFO - Started process (PID=51) to work on /opt/airflow/dags/dbt_advanced.py
[2022-01-28 07:15:05,709] {processor.py:642} INFO - Processing file /opt/airflow/dags/dbt_advanced.py for tasks to queue
[2022-01-28 07:15:05,718] {logging_mixin.py:109} INFO - [2022-01-28 07:15:05,717] {dagbag.py:500} INFO - Filling up the DagBag from /opt/airflow/dags/dbt_advanced.py
[2022-01-28 07:15:05,767] {logging_mixin.py:109} INFO - [2022-01-28 07:15:05,766] {dagbag.py:334} ERROR - Failed to import: /opt/airflow/dags/dbt_advanced.py
Traceback (most recent call last):
  File "/home/airflow/.local/lib/python3.6/site-packages/airflow/models/dagbag.py", line 331, in _load_modules_from_file
    loader.exec_module(new_module)
  File "<frozen importlib._bootstrap_external>", line 678, in exec_module
  File "<frozen importlib._bootstrap>", line 219, in _call_with_frames_removed
  File "/opt/airflow/dags/dbt_advanced.py", line 64, in <module>
    data = load_manifest()
  File "/opt/airflow/dags/dbt_advanced.py", line 25, in load_manifest
    with open(local_filepath) as f:
FileNotFoundError: [Errno 2] No such file or directory: '/usr/local/airflow/dbt/target/manifest.json'
[2022-01-28 07:15:05,838] {processor.py:656} WARNING - No viable dags retrieved from /opt/airflow/dags/dbt_advanced.py
[2022-01-28 07:15:05,894] {processor.py:171} INFO - Processing /opt/airflow/dags/dbt_advanced.py took 0.217 seconds
[2022-01-28 07:15:36,776] {processor.py:163} INFO - Started process (PID=107) to work on /opt/airflow/dags/dbt_advanced.py
[2022-01-28 07:15:36,778] {processor.py:642} INFO - Processing file /opt/airflow/dags/dbt_advanced.py for tasks to queue
[2022-01-28 07:15:36,778] {logging_mixin.py:109} INFO - [2022-01-28 07:15:36,778] {dagbag.py:500} INFO - Filling up the DagBag from /opt/airflow/dags/dbt_advanced.py
[2022-01-28 07:15:36,789] {logging_mixin.py:109} INFO - [2022-01-28 07:15:36,788] {dagbag.py:334} ERROR - Failed to import: /opt/airflow/dags/dbt_advanced.py
Traceback (most recent call last):
  File "/home/airflow/.local/lib/python3.6/site-packages/airflow/models/dagbag.py", line 331, in _load_modules_from_file
    loader.exec_module(new_module)
  File "<frozen importlib._bootstrap_external>", line 678, in exec_module
  File "<frozen importlib._bootstrap>", line 219, in _call_with_frames_removed
  File "/opt/airflow/dags/dbt_advanced.py", line 64, in <module>
    data = load_manifest()
  File "/opt/airflow/dags/dbt_advanced.py", line 25, in load_manifest
    with open(local_filepath) as f:
FileNotFoundError: [Errno 2] No such file or directory: '/usr/local/airflow/dbt/target/manifest.json'
[2022-01-28 07:15:36,809] {processor.py:656} WARNING - No viable dags retrieved from /opt/airflow/dags/dbt_advanced.py
[2022-01-28 07:15:36,819] {processor.py:171} INFO - Processing /opt/airflow/dags/dbt_advanced.py took 0.047 seconds
[2022-01-28 07:16:07,134] {processor.py:163} INFO - Started process (PID=164) to work on /opt/airflow/dags/dbt_advanced.py
[2022-01-28 07:16:07,136] {processor.py:642} INFO - Processing file /opt/airflow/dags/dbt_advanced.py for tasks to queue
[2022-01-28 07:16:07,137] {logging_mixin.py:109} INFO - [2022-01-28 07:16:07,136] {dagbag.py:500} INFO - Filling up the DagBag from /opt/airflow/dags/dbt_advanced.py
[2022-01-28 07:16:07,149] {logging_mixin.py:109} INFO - [2022-01-28 07:16:07,148] {dagbag.py:334} ERROR - Failed to import: /opt/airflow/dags/dbt_advanced.py
Traceback (most recent call last):
  File "/home/airflow/.local/lib/python3.6/site-packages/airflow/models/dagbag.py", line 331, in _load_modules_from_file
    loader.exec_module(new_module)
  File "<frozen importlib._bootstrap_external>", line 678, in exec_module
  File "<frozen importlib._bootstrap>", line 219, in _call_with_frames_removed
  File "/opt/airflow/dags/dbt_advanced.py", line 64, in <module>
    data = load_manifest()
  File "/opt/airflow/dags/dbt_advanced.py", line 25, in load_manifest
    with open(local_filepath) as f:
FileNotFoundError: [Errno 2] No such file or directory: '/usr/local/airflow/dbt/target/manifest.json'
[2022-01-28 07:16:07,172] {processor.py:656} WARNING - No viable dags retrieved from /opt/airflow/dags/dbt_advanced.py
[2022-01-28 07:16:07,181] {processor.py:171} INFO - Processing /opt/airflow/dags/dbt_advanced.py took 0.053 seconds
[2022-01-28 07:16:37,466] {processor.py:163} INFO - Started process (PID=231) to work on /opt/airflow/dags/dbt_advanced.py
[2022-01-28 07:16:37,468] {processor.py:642} INFO - Processing file /opt/airflow/dags/dbt_advanced.py for tasks to queue
[2022-01-28 07:16:37,468] {logging_mixin.py:109} INFO - [2022-01-28 07:16:37,468] {dagbag.py:500} INFO - Filling up the DagBag from /opt/airflow/dags/dbt_advanced.py
[2022-01-28 07:16:37,478] {logging_mixin.py:109} INFO - [2022-01-28 07:16:37,477] {dagbag.py:334} ERROR - Failed to import: /opt/airflow/dags/dbt_advanced.py
Traceback (most recent call last):
  File "/home/airflow/.local/lib/python3.6/site-packages/airflow/models/dagbag.py", line 331, in _load_modules_from_file
    loader.exec_module(new_module)
  File "<frozen importlib._bootstrap_external>", line 678, in exec_module
  File "<frozen importlib._bootstrap>", line 219, in _call_with_frames_removed
  File "/opt/airflow/dags/dbt_advanced.py", line 64, in <module>
    data = load_manifest()
  File "/opt/airflow/dags/dbt_advanced.py", line 25, in load_manifest
    with open(local_filepath) as f:
FileNotFoundError: [Errno 2] No such file or directory: '/usr/local/airflow/dbt/target/manifest.json'
[2022-01-28 07:16:37,496] {processor.py:656} WARNING - No viable dags retrieved from /opt/airflow/dags/dbt_advanced.py
[2022-01-28 07:16:37,505] {processor.py:171} INFO - Processing /opt/airflow/dags/dbt_advanced.py took 0.043 seconds
[2022-01-28 07:17:07,690] {processor.py:163} INFO - Started process (PID=288) to work on /opt/airflow/dags/dbt_advanced.py
[2022-01-28 07:17:07,692] {processor.py:642} INFO - Processing file /opt/airflow/dags/dbt_advanced.py for tasks to queue
[2022-01-28 07:17:07,694] {logging_mixin.py:109} INFO - [2022-01-28 07:17:07,693] {dagbag.py:500} INFO - Filling up the DagBag from /opt/airflow/dags/dbt_advanced.py
[2022-01-28 07:17:07,713] {logging_mixin.py:109} INFO - [2022-01-28 07:17:07,708] {dagbag.py:334} ERROR - Failed to import: /opt/airflow/dags/dbt_advanced.py
Traceback (most recent call last):
  File "/home/airflow/.local/lib/python3.6/site-packages/airflow/models/dagbag.py", line 331, in _load_modules_from_file
    loader.exec_module(new_module)
  File "<frozen importlib._bootstrap_external>", line 678, in exec_module
  File "<frozen importlib._bootstrap>", line 219, in _call_with_frames_removed
  File "/opt/airflow/dags/dbt_advanced.py", line 64, in <module>
    data = load_manifest()
  File "/opt/airflow/dags/dbt_advanced.py", line 25, in load_manifest
    with open(local_filepath) as f:
FileNotFoundError: [Errno 2] No such file or directory: '/usr/local/airflow/dbt/target/manifest.json'
[2022-01-28 07:17:07,736] {processor.py:656} WARNING - No viable dags retrieved from /opt/airflow/dags/dbt_advanced.py
[2022-01-28 07:17:07,743] {processor.py:171} INFO - Processing /opt/airflow/dags/dbt_advanced.py took 0.060 seconds
[2022-01-28 07:17:38,001] {processor.py:163} INFO - Started process (PID=345) to work on /opt/airflow/dags/dbt_advanced.py
[2022-01-28 07:17:38,002] {processor.py:642} INFO - Processing file /opt/airflow/dags/dbt_advanced.py for tasks to queue
[2022-01-28 07:17:38,003] {logging_mixin.py:109} INFO - [2022-01-28 07:17:38,003] {dagbag.py:500} INFO - Filling up the DagBag from /opt/airflow/dags/dbt_advanced.py
[2022-01-28 07:17:38,016] {logging_mixin.py:109} INFO - [2022-01-28 07:17:38,015] {dagbag.py:334} ERROR - Failed to import: /opt/airflow/dags/dbt_advanced.py
Traceback (most recent call last):
  File "/home/airflow/.local/lib/python3.6/site-packages/airflow/models/dagbag.py", line 331, in _load_modules_from_file
    loader.exec_module(new_module)
  File "<frozen importlib._bootstrap_external>", line 678, in exec_module
  File "<frozen importlib._bootstrap>", line 219, in _call_with_frames_removed
  File "/opt/airflow/dags/dbt_advanced.py", line 64, in <module>
    data = load_manifest()
  File "/opt/airflow/dags/dbt_advanced.py", line 25, in load_manifest
    with open(local_filepath) as f:
FileNotFoundError: [Errno 2] No such file or directory: '/usr/local/airflow/dbt/target/manifest.json'
[2022-01-28 07:17:38,036] {processor.py:656} WARNING - No viable dags retrieved from /opt/airflow/dags/dbt_advanced.py
[2022-01-28 07:17:38,047] {processor.py:171} INFO - Processing /opt/airflow/dags/dbt_advanced.py took 0.051 seconds
[2022-01-28 07:18:08,574] {processor.py:163} INFO - Started process (PID=412) to work on /opt/airflow/dags/dbt_advanced.py
[2022-01-28 07:18:08,575] {processor.py:642} INFO - Processing file /opt/airflow/dags/dbt_advanced.py for tasks to queue
[2022-01-28 07:18:08,577] {logging_mixin.py:109} INFO - [2022-01-28 07:18:08,576] {dagbag.py:500} INFO - Filling up the DagBag from /opt/airflow/dags/dbt_advanced.py
[2022-01-28 07:18:08,590] {logging_mixin.py:109} INFO - [2022-01-28 07:18:08,588] {dagbag.py:334} ERROR - Failed to import: /opt/airflow/dags/dbt_advanced.py
Traceback (most recent call last):
  File "/home/airflow/.local/lib/python3.6/site-packages/airflow/models/dagbag.py", line 331, in _load_modules_from_file
    loader.exec_module(new_module)
  File "<frozen importlib._bootstrap_external>", line 678, in exec_module
  File "<frozen importlib._bootstrap>", line 219, in _call_with_frames_removed
  File "/opt/airflow/dags/dbt_advanced.py", line 64, in <module>
    data = load_manifest()
  File "/opt/airflow/dags/dbt_advanced.py", line 25, in load_manifest
    with open(local_filepath) as f:
FileNotFoundError: [Errno 2] No such file or directory: '/usr/local/airflow/dbt/target/manifest.json'
[2022-01-28 07:18:08,611] {processor.py:656} WARNING - No viable dags retrieved from /opt/airflow/dags/dbt_advanced.py
[2022-01-28 07:18:08,621] {processor.py:171} INFO - Processing /opt/airflow/dags/dbt_advanced.py took 0.052 seconds
[2022-01-28 07:18:39,064] {processor.py:163} INFO - Started process (PID=470) to work on /opt/airflow/dags/dbt_advanced.py
[2022-01-28 07:18:39,065] {processor.py:642} INFO - Processing file /opt/airflow/dags/dbt_advanced.py for tasks to queue
[2022-01-28 07:18:39,066] {logging_mixin.py:109} INFO - [2022-01-28 07:18:39,066] {dagbag.py:500} INFO - Filling up the DagBag from /opt/airflow/dags/dbt_advanced.py
[2022-01-28 07:18:39,080] {logging_mixin.py:109} INFO - [2022-01-28 07:18:39,079] {dagbag.py:334} ERROR - Failed to import: /opt/airflow/dags/dbt_advanced.py
Traceback (most recent call last):
  File "/home/airflow/.local/lib/python3.6/site-packages/airflow/models/dagbag.py", line 331, in _load_modules_from_file
    loader.exec_module(new_module)
  File "<frozen importlib._bootstrap_external>", line 678, in exec_module
  File "<frozen importlib._bootstrap>", line 219, in _call_with_frames_removed
  File "/opt/airflow/dags/dbt_advanced.py", line 64, in <module>
    data = load_manifest()
  File "/opt/airflow/dags/dbt_advanced.py", line 25, in load_manifest
    with open(local_filepath) as f:
FileNotFoundError: [Errno 2] No such file or directory: '/usr/local/airflow/dbt/target/manifest.json'
[2022-01-28 07:18:39,103] {processor.py:656} WARNING - No viable dags retrieved from /opt/airflow/dags/dbt_advanced.py
[2022-01-28 07:18:39,113] {processor.py:171} INFO - Processing /opt/airflow/dags/dbt_advanced.py took 0.055 seconds
[2022-01-28 07:19:09,803] {processor.py:163} INFO - Started process (PID=527) to work on /opt/airflow/dags/dbt_advanced.py
[2022-01-28 07:19:09,804] {processor.py:642} INFO - Processing file /opt/airflow/dags/dbt_advanced.py for tasks to queue
[2022-01-28 07:19:09,805] {logging_mixin.py:109} INFO - [2022-01-28 07:19:09,805] {dagbag.py:500} INFO - Filling up the DagBag from /opt/airflow/dags/dbt_advanced.py
[2022-01-28 07:19:09,819] {logging_mixin.py:109} INFO - [2022-01-28 07:19:09,818] {dagbag.py:334} ERROR - Failed to import: /opt/airflow/dags/dbt_advanced.py
Traceback (most recent call last):
  File "/home/airflow/.local/lib/python3.6/site-packages/airflow/models/dagbag.py", line 331, in _load_modules_from_file
    loader.exec_module(new_module)
  File "<frozen importlib._bootstrap_external>", line 678, in exec_module
  File "<frozen importlib._bootstrap>", line 219, in _call_with_frames_removed
  File "/opt/airflow/dags/dbt_advanced.py", line 64, in <module>
    data = load_manifest()
  File "/opt/airflow/dags/dbt_advanced.py", line 25, in load_manifest
    with open(local_filepath) as f:
FileNotFoundError: [Errno 2] No such file or directory: '/usr/local/airflow/dbt/target/manifest.json'
[2022-01-28 07:19:09,849] {processor.py:656} WARNING - No viable dags retrieved from /opt/airflow/dags/dbt_advanced.py
[2022-01-28 07:19:09,858] {processor.py:171} INFO - Processing /opt/airflow/dags/dbt_advanced.py took 0.059 seconds
[2022-01-28 07:19:40,313] {processor.py:163} INFO - Started process (PID=597) to work on /opt/airflow/dags/dbt_advanced.py
[2022-01-28 07:19:40,314] {processor.py:642} INFO - Processing file /opt/airflow/dags/dbt_advanced.py for tasks to queue
[2022-01-28 07:19:40,315] {logging_mixin.py:109} INFO - [2022-01-28 07:19:40,315] {dagbag.py:500} INFO - Filling up the DagBag from /opt/airflow/dags/dbt_advanced.py
[2022-01-28 07:19:40,326] {logging_mixin.py:109} INFO - [2022-01-28 07:19:40,325] {dagbag.py:334} ERROR - Failed to import: /opt/airflow/dags/dbt_advanced.py
Traceback (most recent call last):
  File "/home/airflow/.local/lib/python3.6/site-packages/airflow/models/dagbag.py", line 331, in _load_modules_from_file
    loader.exec_module(new_module)
  File "<frozen importlib._bootstrap_external>", line 678, in exec_module
  File "<frozen importlib._bootstrap>", line 219, in _call_with_frames_removed
  File "/opt/airflow/dags/dbt_advanced.py", line 64, in <module>
    data = load_manifest()
  File "/opt/airflow/dags/dbt_advanced.py", line 25, in load_manifest
    with open(local_filepath) as f:
FileNotFoundError: [Errno 2] No such file or directory: '/usr/local/airflow/dbt/target/manifest.json'
[2022-01-28 07:19:40,349] {processor.py:656} WARNING - No viable dags retrieved from /opt/airflow/dags/dbt_advanced.py
[2022-01-28 07:19:40,359] {processor.py:171} INFO - Processing /opt/airflow/dags/dbt_advanced.py took 0.051 seconds
[2022-01-28 07:20:10,758] {processor.py:163} INFO - Started process (PID=655) to work on /opt/airflow/dags/dbt_advanced.py
[2022-01-28 07:20:10,760] {processor.py:642} INFO - Processing file /opt/airflow/dags/dbt_advanced.py for tasks to queue
[2022-01-28 07:20:10,761] {logging_mixin.py:109} INFO - [2022-01-28 07:20:10,761] {dagbag.py:500} INFO - Filling up the DagBag from /opt/airflow/dags/dbt_advanced.py
[2022-01-28 07:20:10,771] {logging_mixin.py:109} INFO - [2022-01-28 07:20:10,770] {dagbag.py:334} ERROR - Failed to import: /opt/airflow/dags/dbt_advanced.py
Traceback (most recent call last):
  File "/home/airflow/.local/lib/python3.6/site-packages/airflow/models/dagbag.py", line 331, in _load_modules_from_file
    loader.exec_module(new_module)
  File "<frozen importlib._bootstrap_external>", line 678, in exec_module
  File "<frozen importlib._bootstrap>", line 219, in _call_with_frames_removed
  File "/opt/airflow/dags/dbt_advanced.py", line 64, in <module>
    data = load_manifest()
  File "/opt/airflow/dags/dbt_advanced.py", line 25, in load_manifest
    with open(local_filepath) as f:
FileNotFoundError: [Errno 2] No such file or directory: '/usr/local/airflow/dbt/target/manifest.json'
[2022-01-28 07:20:10,794] {processor.py:656} WARNING - No viable dags retrieved from /opt/airflow/dags/dbt_advanced.py
[2022-01-28 07:20:10,804] {processor.py:171} INFO - Processing /opt/airflow/dags/dbt_advanced.py took 0.051 seconds
[2022-01-28 07:20:41,219] {processor.py:163} INFO - Started process (PID=714) to work on /opt/airflow/dags/dbt_advanced.py
[2022-01-28 07:20:41,220] {processor.py:642} INFO - Processing file /opt/airflow/dags/dbt_advanced.py for tasks to queue
[2022-01-28 07:20:41,221] {logging_mixin.py:109} INFO - [2022-01-28 07:20:41,221] {dagbag.py:500} INFO - Filling up the DagBag from /opt/airflow/dags/dbt_advanced.py
[2022-01-28 07:20:41,231] {logging_mixin.py:109} INFO - [2022-01-28 07:20:41,230] {dagbag.py:334} ERROR - Failed to import: /opt/airflow/dags/dbt_advanced.py
Traceback (most recent call last):
  File "/home/airflow/.local/lib/python3.6/site-packages/airflow/models/dagbag.py", line 331, in _load_modules_from_file
    loader.exec_module(new_module)
  File "<frozen importlib._bootstrap_external>", line 678, in exec_module
  File "<frozen importlib._bootstrap>", line 219, in _call_with_frames_removed
  File "/opt/airflow/dags/dbt_advanced.py", line 64, in <module>
    data = load_manifest()
  File "/opt/airflow/dags/dbt_advanced.py", line 25, in load_manifest
    with open(local_filepath) as f:
FileNotFoundError: [Errno 2] No such file or directory: '/usr/local/airflow/dbt/target/manifest.json'
[2022-01-28 07:20:41,250] {processor.py:656} WARNING - No viable dags retrieved from /opt/airflow/dags/dbt_advanced.py
[2022-01-28 07:20:41,259] {processor.py:171} INFO - Processing /opt/airflow/dags/dbt_advanced.py took 0.044 seconds
[2022-01-28 07:21:11,766] {processor.py:163} INFO - Started process (PID=780) to work on /opt/airflow/dags/dbt_advanced.py
[2022-01-28 07:21:11,778] {processor.py:642} INFO - Processing file /opt/airflow/dags/dbt_advanced.py for tasks to queue
[2022-01-28 07:21:11,779] {logging_mixin.py:109} INFO - [2022-01-28 07:21:11,779] {dagbag.py:500} INFO - Filling up the DagBag from /opt/airflow/dags/dbt_advanced.py
[2022-01-28 07:21:11,788] {logging_mixin.py:109} INFO - [2022-01-28 07:21:11,787] {dagbag.py:334} ERROR - Failed to import: /opt/airflow/dags/dbt_advanced.py
Traceback (most recent call last):
  File "/home/airflow/.local/lib/python3.6/site-packages/airflow/models/dagbag.py", line 331, in _load_modules_from_file
    loader.exec_module(new_module)
  File "<frozen importlib._bootstrap_external>", line 678, in exec_module
  File "<frozen importlib._bootstrap>", line 219, in _call_with_frames_removed
  File "/opt/airflow/dags/dbt_advanced.py", line 64, in <module>
    data = load_manifest()
  File "/opt/airflow/dags/dbt_advanced.py", line 25, in load_manifest
    with open(local_filepath) as f:
FileNotFoundError: [Errno 2] No such file or directory: '/usr/local/airflow/dbt/target/manifest.json'
[2022-01-28 07:21:11,817] {processor.py:656} WARNING - No viable dags retrieved from /opt/airflow/dags/dbt_advanced.py
[2022-01-28 07:21:11,832] {processor.py:171} INFO - Processing /opt/airflow/dags/dbt_advanced.py took 0.071 seconds
[2022-01-28 07:21:42,343] {processor.py:163} INFO - Started process (PID=840) to work on /opt/airflow/dags/dbt_advanced.py
[2022-01-28 07:21:42,345] {processor.py:642} INFO - Processing file /opt/airflow/dags/dbt_advanced.py for tasks to queue
[2022-01-28 07:21:42,346] {logging_mixin.py:109} INFO - [2022-01-28 07:21:42,345] {dagbag.py:500} INFO - Filling up the DagBag from /opt/airflow/dags/dbt_advanced.py
[2022-01-28 07:21:42,361] {logging_mixin.py:109} INFO - [2022-01-28 07:21:42,360] {dagbag.py:334} ERROR - Failed to import: /opt/airflow/dags/dbt_advanced.py
Traceback (most recent call last):
  File "/home/airflow/.local/lib/python3.6/site-packages/airflow/models/dagbag.py", line 331, in _load_modules_from_file
    loader.exec_module(new_module)
  File "<frozen importlib._bootstrap_external>", line 678, in exec_module
  File "<frozen importlib._bootstrap>", line 219, in _call_with_frames_removed
  File "/opt/airflow/dags/dbt_advanced.py", line 64, in <module>
    data = load_manifest()
  File "/opt/airflow/dags/dbt_advanced.py", line 25, in load_manifest
    with open(local_filepath) as f:
FileNotFoundError: [Errno 2] No such file or directory: '/usr/local/airflow/dbt/target/manifest.json'
[2022-01-28 07:21:42,381] {processor.py:656} WARNING - No viable dags retrieved from /opt/airflow/dags/dbt_advanced.py
[2022-01-28 07:21:42,389] {processor.py:171} INFO - Processing /opt/airflow/dags/dbt_advanced.py took 0.052 seconds
[2022-01-28 07:22:12,855] {processor.py:163} INFO - Started process (PID=898) to work on /opt/airflow/dags/dbt_advanced.py
[2022-01-28 07:22:12,857] {processor.py:642} INFO - Processing file /opt/airflow/dags/dbt_advanced.py for tasks to queue
[2022-01-28 07:22:12,858] {logging_mixin.py:109} INFO - [2022-01-28 07:22:12,858] {dagbag.py:500} INFO - Filling up the DagBag from /opt/airflow/dags/dbt_advanced.py
[2022-01-28 07:22:12,880] {logging_mixin.py:109} INFO - [2022-01-28 07:22:12,878] {dagbag.py:334} ERROR - Failed to import: /opt/airflow/dags/dbt_advanced.py
Traceback (most recent call last):
  File "/home/airflow/.local/lib/python3.6/site-packages/airflow/models/dagbag.py", line 331, in _load_modules_from_file
    loader.exec_module(new_module)
  File "<frozen importlib._bootstrap_external>", line 678, in exec_module
  File "<frozen importlib._bootstrap>", line 219, in _call_with_frames_removed
  File "/opt/airflow/dags/dbt_advanced.py", line 64, in <module>
    data = load_manifest()
  File "/opt/airflow/dags/dbt_advanced.py", line 25, in load_manifest
    with open(local_filepath) as f:
FileNotFoundError: [Errno 2] No such file or directory: '/usr/local/airflow/dbt/target/manifest.json'
[2022-01-28 07:22:12,905] {processor.py:656} WARNING - No viable dags retrieved from /opt/airflow/dags/dbt_advanced.py
[2022-01-28 07:22:12,916] {processor.py:171} INFO - Processing /opt/airflow/dags/dbt_advanced.py took 0.067 seconds
[2022-01-28 07:22:43,351] {processor.py:163} INFO - Started process (PID=961) to work on /opt/airflow/dags/dbt_advanced.py
[2022-01-28 07:22:43,353] {processor.py:642} INFO - Processing file /opt/airflow/dags/dbt_advanced.py for tasks to queue
[2022-01-28 07:22:43,354] {logging_mixin.py:109} INFO - [2022-01-28 07:22:43,354] {dagbag.py:500} INFO - Filling up the DagBag from /opt/airflow/dags/dbt_advanced.py
[2022-01-28 07:22:43,369] {logging_mixin.py:109} INFO - [2022-01-28 07:22:43,367] {dagbag.py:334} ERROR - Failed to import: /opt/airflow/dags/dbt_advanced.py
Traceback (most recent call last):
  File "/home/airflow/.local/lib/python3.6/site-packages/airflow/models/dagbag.py", line 331, in _load_modules_from_file
    loader.exec_module(new_module)
  File "<frozen importlib._bootstrap_external>", line 678, in exec_module
  File "<frozen importlib._bootstrap>", line 219, in _call_with_frames_removed
  File "/opt/airflow/dags/dbt_advanced.py", line 64, in <module>
    data = load_manifest()
  File "/opt/airflow/dags/dbt_advanced.py", line 25, in load_manifest
    with open(local_filepath) as f:
FileNotFoundError: [Errno 2] No such file or directory: '/usr/local/airflow/dbt/target/manifest.json'
[2022-01-28 07:22:43,392] {processor.py:656} WARNING - No viable dags retrieved from /opt/airflow/dags/dbt_advanced.py
[2022-01-28 07:22:43,402] {processor.py:171} INFO - Processing /opt/airflow/dags/dbt_advanced.py took 0.057 seconds
[2022-01-28 07:23:13,488] {processor.py:163} INFO - Started process (PID=1021) to work on /opt/airflow/dags/dbt_advanced.py
[2022-01-28 07:23:13,489] {processor.py:642} INFO - Processing file /opt/airflow/dags/dbt_advanced.py for tasks to queue
[2022-01-28 07:23:13,490] {logging_mixin.py:109} INFO - [2022-01-28 07:23:13,490] {dagbag.py:500} INFO - Filling up the DagBag from /opt/airflow/dags/dbt_advanced.py
[2022-01-28 07:23:13,500] {logging_mixin.py:109} INFO - [2022-01-28 07:23:13,499] {dagbag.py:334} ERROR - Failed to import: /opt/airflow/dags/dbt_advanced.py
Traceback (most recent call last):
  File "/home/airflow/.local/lib/python3.6/site-packages/airflow/models/dagbag.py", line 331, in _load_modules_from_file
    loader.exec_module(new_module)
  File "<frozen importlib._bootstrap_external>", line 678, in exec_module
  File "<frozen importlib._bootstrap>", line 219, in _call_with_frames_removed
  File "/opt/airflow/dags/dbt_advanced.py", line 64, in <module>
    data = load_manifest()
  File "/opt/airflow/dags/dbt_advanced.py", line 25, in load_manifest
    with open(local_filepath) as f:
FileNotFoundError: [Errno 2] No such file or directory: '/usr/local/airflow/dbt/target/manifest.json'
[2022-01-28 07:23:13,520] {processor.py:656} WARNING - No viable dags retrieved from /opt/airflow/dags/dbt_advanced.py
[2022-01-28 07:23:13,531] {processor.py:171} INFO - Processing /opt/airflow/dags/dbt_advanced.py took 0.048 seconds
[2022-01-28 07:23:44,228] {processor.py:163} INFO - Started process (PID=1080) to work on /opt/airflow/dags/dbt_advanced.py
[2022-01-28 07:23:44,229] {processor.py:642} INFO - Processing file /opt/airflow/dags/dbt_advanced.py for tasks to queue
[2022-01-28 07:23:44,230] {logging_mixin.py:109} INFO - [2022-01-28 07:23:44,230] {dagbag.py:500} INFO - Filling up the DagBag from /opt/airflow/dags/dbt_advanced.py
[2022-01-28 07:23:44,241] {logging_mixin.py:109} INFO - [2022-01-28 07:23:44,239] {dagbag.py:334} ERROR - Failed to import: /opt/airflow/dags/dbt_advanced.py
Traceback (most recent call last):
  File "/home/airflow/.local/lib/python3.6/site-packages/airflow/models/dagbag.py", line 331, in _load_modules_from_file
    loader.exec_module(new_module)
  File "<frozen importlib._bootstrap_external>", line 678, in exec_module
  File "<frozen importlib._bootstrap>", line 219, in _call_with_frames_removed
  File "/opt/airflow/dags/dbt_advanced.py", line 64, in <module>
    data = load_manifest()
  File "/opt/airflow/dags/dbt_advanced.py", line 25, in load_manifest
    with open(local_filepath) as f:
FileNotFoundError: [Errno 2] No such file or directory: '/usr/local/airflow/dbt/target/manifest.json'
[2022-01-28 07:23:44,262] {processor.py:656} WARNING - No viable dags retrieved from /opt/airflow/dags/dbt_advanced.py
[2022-01-28 07:23:44,274] {processor.py:171} INFO - Processing /opt/airflow/dags/dbt_advanced.py took 0.051 seconds
[2022-01-28 07:24:14,752] {processor.py:163} INFO - Started process (PID=1137) to work on /opt/airflow/dags/dbt_advanced.py
[2022-01-28 07:24:14,753] {processor.py:642} INFO - Processing file /opt/airflow/dags/dbt_advanced.py for tasks to queue
[2022-01-28 07:24:14,754] {logging_mixin.py:109} INFO - [2022-01-28 07:24:14,754] {dagbag.py:500} INFO - Filling up the DagBag from /opt/airflow/dags/dbt_advanced.py
[2022-01-28 07:24:14,763] {logging_mixin.py:109} INFO - [2022-01-28 07:24:14,763] {dagbag.py:334} ERROR - Failed to import: /opt/airflow/dags/dbt_advanced.py
Traceback (most recent call last):
  File "/home/airflow/.local/lib/python3.6/site-packages/airflow/models/dagbag.py", line 331, in _load_modules_from_file
    loader.exec_module(new_module)
  File "<frozen importlib._bootstrap_external>", line 678, in exec_module
  File "<frozen importlib._bootstrap>", line 219, in _call_with_frames_removed
  File "/opt/airflow/dags/dbt_advanced.py", line 64, in <module>
    data = load_manifest()
  File "/opt/airflow/dags/dbt_advanced.py", line 25, in load_manifest
    with open(local_filepath) as f:
FileNotFoundError: [Errno 2] No such file or directory: '/usr/local/airflow/dbt/target/manifest.json'
[2022-01-28 07:24:14,780] {processor.py:656} WARNING - No viable dags retrieved from /opt/airflow/dags/dbt_advanced.py
[2022-01-28 07:24:14,790] {processor.py:171} INFO - Processing /opt/airflow/dags/dbt_advanced.py took 0.042 seconds
[2022-01-28 07:24:45,420] {processor.py:163} INFO - Started process (PID=1207) to work on /opt/airflow/dags/dbt_advanced.py
[2022-01-28 07:24:45,422] {processor.py:642} INFO - Processing file /opt/airflow/dags/dbt_advanced.py for tasks to queue
[2022-01-28 07:24:45,422] {logging_mixin.py:109} INFO - [2022-01-28 07:24:45,422] {dagbag.py:500} INFO - Filling up the DagBag from /opt/airflow/dags/dbt_advanced.py
[2022-01-28 07:24:45,433] {logging_mixin.py:109} INFO - [2022-01-28 07:24:45,432] {dagbag.py:334} ERROR - Failed to import: /opt/airflow/dags/dbt_advanced.py
Traceback (most recent call last):
  File "/home/airflow/.local/lib/python3.6/site-packages/airflow/models/dagbag.py", line 331, in _load_modules_from_file
    loader.exec_module(new_module)
  File "<frozen importlib._bootstrap_external>", line 678, in exec_module
  File "<frozen importlib._bootstrap>", line 219, in _call_with_frames_removed
  File "/opt/airflow/dags/dbt_advanced.py", line 64, in <module>
    data = load_manifest()
  File "/opt/airflow/dags/dbt_advanced.py", line 25, in load_manifest
    with open(local_filepath) as f:
FileNotFoundError: [Errno 2] No such file or directory: '/usr/local/airflow/dbt/target/manifest.json'
[2022-01-28 07:24:45,454] {processor.py:656} WARNING - No viable dags retrieved from /opt/airflow/dags/dbt_advanced.py
[2022-01-28 07:24:45,465] {processor.py:171} INFO - Processing /opt/airflow/dags/dbt_advanced.py took 0.049 seconds
[2022-01-28 07:25:16,045] {processor.py:163} INFO - Started process (PID=1263) to work on /opt/airflow/dags/dbt_advanced.py
[2022-01-28 07:25:16,047] {processor.py:642} INFO - Processing file /opt/airflow/dags/dbt_advanced.py for tasks to queue
[2022-01-28 07:25:16,048] {logging_mixin.py:109} INFO - [2022-01-28 07:25:16,048] {dagbag.py:500} INFO - Filling up the DagBag from /opt/airflow/dags/dbt_advanced.py
[2022-01-28 07:25:16,062] {logging_mixin.py:109} INFO - [2022-01-28 07:25:16,061] {dagbag.py:334} ERROR - Failed to import: /opt/airflow/dags/dbt_advanced.py
Traceback (most recent call last):
  File "/home/airflow/.local/lib/python3.6/site-packages/airflow/models/dagbag.py", line 331, in _load_modules_from_file
    loader.exec_module(new_module)
  File "<frozen importlib._bootstrap_external>", line 678, in exec_module
  File "<frozen importlib._bootstrap>", line 219, in _call_with_frames_removed
  File "/opt/airflow/dags/dbt_advanced.py", line 64, in <module>
    data = load_manifest()
  File "/opt/airflow/dags/dbt_advanced.py", line 25, in load_manifest
    with open(local_filepath) as f:
FileNotFoundError: [Errno 2] No such file or directory: '/usr/local/airflow/dbt/target/manifest.json'
[2022-01-28 07:25:16,084] {processor.py:656} WARNING - No viable dags retrieved from /opt/airflow/dags/dbt_advanced.py
[2022-01-28 07:25:16,094] {processor.py:171} INFO - Processing /opt/airflow/dags/dbt_advanced.py took 0.056 seconds
[2022-01-28 07:25:46,947] {processor.py:163} INFO - Started process (PID=1322) to work on /opt/airflow/dags/dbt_advanced.py
[2022-01-28 07:25:46,950] {processor.py:642} INFO - Processing file /opt/airflow/dags/dbt_advanced.py for tasks to queue
[2022-01-28 07:25:46,951] {logging_mixin.py:109} INFO - [2022-01-28 07:25:46,951] {dagbag.py:500} INFO - Filling up the DagBag from /opt/airflow/dags/dbt_advanced.py
[2022-01-28 07:25:46,967] {logging_mixin.py:109} INFO - [2022-01-28 07:25:46,965] {dagbag.py:334} ERROR - Failed to import: /opt/airflow/dags/dbt_advanced.py
Traceback (most recent call last):
  File "/home/airflow/.local/lib/python3.6/site-packages/airflow/models/dagbag.py", line 331, in _load_modules_from_file
    loader.exec_module(new_module)
  File "<frozen importlib._bootstrap_external>", line 678, in exec_module
  File "<frozen importlib._bootstrap>", line 219, in _call_with_frames_removed
  File "/opt/airflow/dags/dbt_advanced.py", line 64, in <module>
    data = load_manifest()
  File "/opt/airflow/dags/dbt_advanced.py", line 25, in load_manifest
    with open(local_filepath) as f:
FileNotFoundError: [Errno 2] No such file or directory: '/usr/local/airflow/dbt/target/manifest.json'
[2022-01-28 07:25:46,991] {processor.py:656} WARNING - No viable dags retrieved from /opt/airflow/dags/dbt_advanced.py
[2022-01-28 07:25:47,005] {processor.py:171} INFO - Processing /opt/airflow/dags/dbt_advanced.py took 0.064 seconds
[2022-01-28 07:26:17,419] {processor.py:163} INFO - Started process (PID=1389) to work on /opt/airflow/dags/dbt_advanced.py
[2022-01-28 07:26:17,421] {processor.py:642} INFO - Processing file /opt/airflow/dags/dbt_advanced.py for tasks to queue
[2022-01-28 07:26:17,422] {logging_mixin.py:109} INFO - [2022-01-28 07:26:17,422] {dagbag.py:500} INFO - Filling up the DagBag from /opt/airflow/dags/dbt_advanced.py
[2022-01-28 07:26:17,432] {logging_mixin.py:109} INFO - [2022-01-28 07:26:17,431] {dagbag.py:334} ERROR - Failed to import: /opt/airflow/dags/dbt_advanced.py
Traceback (most recent call last):
  File "/home/airflow/.local/lib/python3.6/site-packages/airflow/models/dagbag.py", line 331, in _load_modules_from_file
    loader.exec_module(new_module)
  File "<frozen importlib._bootstrap_external>", line 678, in exec_module
  File "<frozen importlib._bootstrap>", line 219, in _call_with_frames_removed
  File "/opt/airflow/dags/dbt_advanced.py", line 64, in <module>
    data = load_manifest()
  File "/opt/airflow/dags/dbt_advanced.py", line 25, in load_manifest
    with open(local_filepath) as f:
FileNotFoundError: [Errno 2] No such file or directory: '/usr/local/airflow/dbt/target/manifest.json'
[2022-01-28 07:26:17,454] {processor.py:656} WARNING - No viable dags retrieved from /opt/airflow/dags/dbt_advanced.py
[2022-01-28 07:26:17,465] {processor.py:171} INFO - Processing /opt/airflow/dags/dbt_advanced.py took 0.051 seconds
[2022-01-28 07:26:47,952] {processor.py:163} INFO - Started process (PID=1447) to work on /opt/airflow/dags/dbt_advanced.py
[2022-01-28 07:26:47,954] {processor.py:642} INFO - Processing file /opt/airflow/dags/dbt_advanced.py for tasks to queue
[2022-01-28 07:26:47,955] {logging_mixin.py:109} INFO - [2022-01-28 07:26:47,954] {dagbag.py:500} INFO - Filling up the DagBag from /opt/airflow/dags/dbt_advanced.py
[2022-01-28 07:26:47,965] {logging_mixin.py:109} INFO - [2022-01-28 07:26:47,964] {dagbag.py:334} ERROR - Failed to import: /opt/airflow/dags/dbt_advanced.py
Traceback (most recent call last):
  File "/home/airflow/.local/lib/python3.6/site-packages/airflow/models/dagbag.py", line 331, in _load_modules_from_file
    loader.exec_module(new_module)
  File "<frozen importlib._bootstrap_external>", line 678, in exec_module
  File "<frozen importlib._bootstrap>", line 219, in _call_with_frames_removed
  File "/opt/airflow/dags/dbt_advanced.py", line 64, in <module>
    data = load_manifest()
  File "/opt/airflow/dags/dbt_advanced.py", line 25, in load_manifest
    with open(local_filepath) as f:
FileNotFoundError: [Errno 2] No such file or directory: '/usr/local/airflow/dbt/target/manifest.json'
[2022-01-28 07:26:47,988] {processor.py:656} WARNING - No viable dags retrieved from /opt/airflow/dags/dbt_advanced.py
[2022-01-28 07:26:48,004] {processor.py:171} INFO - Processing /opt/airflow/dags/dbt_advanced.py took 0.056 seconds
[2022-01-28 07:27:18,422] {processor.py:163} INFO - Started process (PID=1504) to work on /opt/airflow/dags/dbt_advanced.py
[2022-01-28 07:27:18,424] {processor.py:642} INFO - Processing file /opt/airflow/dags/dbt_advanced.py for tasks to queue
[2022-01-28 07:27:18,425] {logging_mixin.py:109} INFO - [2022-01-28 07:27:18,425] {dagbag.py:500} INFO - Filling up the DagBag from /opt/airflow/dags/dbt_advanced.py
[2022-01-28 07:27:18,438] {logging_mixin.py:109} INFO - [2022-01-28 07:27:18,437] {dagbag.py:334} ERROR - Failed to import: /opt/airflow/dags/dbt_advanced.py
Traceback (most recent call last):
  File "/home/airflow/.local/lib/python3.6/site-packages/airflow/models/dagbag.py", line 331, in _load_modules_from_file
    loader.exec_module(new_module)
  File "<frozen importlib._bootstrap_external>", line 678, in exec_module
  File "<frozen importlib._bootstrap>", line 219, in _call_with_frames_removed
  File "/opt/airflow/dags/dbt_advanced.py", line 64, in <module>
    data = load_manifest()
  File "/opt/airflow/dags/dbt_advanced.py", line 25, in load_manifest
    with open(local_filepath) as f:
FileNotFoundError: [Errno 2] No such file or directory: '/usr/local/airflow/dbt/target/manifest.json'
[2022-01-28 07:27:18,460] {processor.py:656} WARNING - No viable dags retrieved from /opt/airflow/dags/dbt_advanced.py
[2022-01-28 07:27:18,471] {processor.py:171} INFO - Processing /opt/airflow/dags/dbt_advanced.py took 0.054 seconds
[2022-01-28 07:27:48,830] {processor.py:163} INFO - Started process (PID=1573) to work on /opt/airflow/dags/dbt_advanced.py
[2022-01-28 07:27:48,832] {processor.py:642} INFO - Processing file /opt/airflow/dags/dbt_advanced.py for tasks to queue
[2022-01-28 07:27:48,833] {logging_mixin.py:109} INFO - [2022-01-28 07:27:48,833] {dagbag.py:500} INFO - Filling up the DagBag from /opt/airflow/dags/dbt_advanced.py
[2022-01-28 07:27:48,843] {logging_mixin.py:109} INFO - [2022-01-28 07:27:48,842] {dagbag.py:334} ERROR - Failed to import: /opt/airflow/dags/dbt_advanced.py
Traceback (most recent call last):
  File "/home/airflow/.local/lib/python3.6/site-packages/airflow/models/dagbag.py", line 331, in _load_modules_from_file
    loader.exec_module(new_module)
  File "<frozen importlib._bootstrap_external>", line 678, in exec_module
  File "<frozen importlib._bootstrap>", line 219, in _call_with_frames_removed
  File "/opt/airflow/dags/dbt_advanced.py", line 64, in <module>
    data = load_manifest()
  File "/opt/airflow/dags/dbt_advanced.py", line 25, in load_manifest
    with open(local_filepath) as f:
FileNotFoundError: [Errno 2] No such file or directory: '/usr/local/airflow/dbt/target/manifest.json'
[2022-01-28 07:27:48,861] {processor.py:656} WARNING - No viable dags retrieved from /opt/airflow/dags/dbt_advanced.py
[2022-01-28 07:27:48,870] {processor.py:171} INFO - Processing /opt/airflow/dags/dbt_advanced.py took 0.045 seconds
[2022-01-28 07:28:19,022] {processor.py:163} INFO - Started process (PID=1630) to work on /opt/airflow/dags/dbt_advanced.py
[2022-01-28 07:28:19,023] {processor.py:642} INFO - Processing file /opt/airflow/dags/dbt_advanced.py for tasks to queue
[2022-01-28 07:28:19,024] {logging_mixin.py:109} INFO - [2022-01-28 07:28:19,024] {dagbag.py:500} INFO - Filling up the DagBag from /opt/airflow/dags/dbt_advanced.py
[2022-01-28 07:28:19,034] {logging_mixin.py:109} INFO - [2022-01-28 07:28:19,033] {dagbag.py:334} ERROR - Failed to import: /opt/airflow/dags/dbt_advanced.py
Traceback (most recent call last):
  File "/home/airflow/.local/lib/python3.6/site-packages/airflow/models/dagbag.py", line 331, in _load_modules_from_file
    loader.exec_module(new_module)
  File "<frozen importlib._bootstrap_external>", line 678, in exec_module
  File "<frozen importlib._bootstrap>", line 219, in _call_with_frames_removed
  File "/opt/airflow/dags/dbt_advanced.py", line 64, in <module>
    data = load_manifest()
  File "/opt/airflow/dags/dbt_advanced.py", line 25, in load_manifest
    with open(local_filepath) as f:
FileNotFoundError: [Errno 2] No such file or directory: '/usr/local/airflow/dbt/target/manifest.json'
[2022-01-28 07:28:19,056] {processor.py:656} WARNING - No viable dags retrieved from /opt/airflow/dags/dbt_advanced.py
[2022-01-28 07:28:19,066] {processor.py:171} INFO - Processing /opt/airflow/dags/dbt_advanced.py took 0.048 seconds
[2022-01-28 07:28:49,565] {processor.py:163} INFO - Started process (PID=1688) to work on /opt/airflow/dags/dbt_advanced.py
[2022-01-28 07:28:49,567] {processor.py:642} INFO - Processing file /opt/airflow/dags/dbt_advanced.py for tasks to queue
[2022-01-28 07:28:49,568] {logging_mixin.py:109} INFO - [2022-01-28 07:28:49,568] {dagbag.py:500} INFO - Filling up the DagBag from /opt/airflow/dags/dbt_advanced.py
[2022-01-28 07:28:49,579] {logging_mixin.py:109} INFO - [2022-01-28 07:28:49,578] {dagbag.py:334} ERROR - Failed to import: /opt/airflow/dags/dbt_advanced.py
Traceback (most recent call last):
  File "/home/airflow/.local/lib/python3.6/site-packages/airflow/models/dagbag.py", line 331, in _load_modules_from_file
    loader.exec_module(new_module)
  File "<frozen importlib._bootstrap_external>", line 678, in exec_module
  File "<frozen importlib._bootstrap>", line 219, in _call_with_frames_removed
  File "/opt/airflow/dags/dbt_advanced.py", line 64, in <module>
    data = load_manifest()
  File "/opt/airflow/dags/dbt_advanced.py", line 25, in load_manifest
    with open(local_filepath) as f:
FileNotFoundError: [Errno 2] No such file or directory: '/usr/local/airflow/dbt/target/manifest.json'
[2022-01-28 07:28:49,597] {processor.py:656} WARNING - No viable dags retrieved from /opt/airflow/dags/dbt_advanced.py
[2022-01-28 07:28:49,651] {processor.py:171} INFO - Processing /opt/airflow/dags/dbt_advanced.py took 0.090 seconds
[2022-01-28 07:29:20,099] {processor.py:163} INFO - Started process (PID=1755) to work on /opt/airflow/dags/dbt_advanced.py
[2022-01-28 07:29:20,100] {processor.py:642} INFO - Processing file /opt/airflow/dags/dbt_advanced.py for tasks to queue
[2022-01-28 07:29:20,101] {logging_mixin.py:109} INFO - [2022-01-28 07:29:20,101] {dagbag.py:500} INFO - Filling up the DagBag from /opt/airflow/dags/dbt_advanced.py
[2022-01-28 07:29:20,113] {logging_mixin.py:109} INFO - [2022-01-28 07:29:20,112] {dagbag.py:334} ERROR - Failed to import: /opt/airflow/dags/dbt_advanced.py
Traceback (most recent call last):
  File "/home/airflow/.local/lib/python3.6/site-packages/airflow/models/dagbag.py", line 331, in _load_modules_from_file
    loader.exec_module(new_module)
  File "<frozen importlib._bootstrap_external>", line 678, in exec_module
  File "<frozen importlib._bootstrap>", line 219, in _call_with_frames_removed
  File "/opt/airflow/dags/dbt_advanced.py", line 64, in <module>
    data = load_manifest()
  File "/opt/airflow/dags/dbt_advanced.py", line 25, in load_manifest
    with open(local_filepath) as f:
FileNotFoundError: [Errno 2] No such file or directory: '/usr/local/airflow/dbt/target/manifest.json'
[2022-01-28 07:29:20,131] {processor.py:656} WARNING - No viable dags retrieved from /opt/airflow/dags/dbt_advanced.py
[2022-01-28 07:29:20,139] {processor.py:171} INFO - Processing /opt/airflow/dags/dbt_advanced.py took 0.045 seconds
[2022-01-28 07:29:50,572] {processor.py:163} INFO - Started process (PID=1811) to work on /opt/airflow/dags/dbt_advanced.py
[2022-01-28 07:29:50,574] {processor.py:642} INFO - Processing file /opt/airflow/dags/dbt_advanced.py for tasks to queue
[2022-01-28 07:29:50,574] {logging_mixin.py:109} INFO - [2022-01-28 07:29:50,574] {dagbag.py:500} INFO - Filling up the DagBag from /opt/airflow/dags/dbt_advanced.py
[2022-01-28 07:29:50,585] {logging_mixin.py:109} INFO - [2022-01-28 07:29:50,584] {dagbag.py:334} ERROR - Failed to import: /opt/airflow/dags/dbt_advanced.py
Traceback (most recent call last):
  File "/home/airflow/.local/lib/python3.6/site-packages/airflow/models/dagbag.py", line 331, in _load_modules_from_file
    loader.exec_module(new_module)
  File "<frozen importlib._bootstrap_external>", line 678, in exec_module
  File "<frozen importlib._bootstrap>", line 219, in _call_with_frames_removed
  File "/opt/airflow/dags/dbt_advanced.py", line 64, in <module>
    data = load_manifest()
  File "/opt/airflow/dags/dbt_advanced.py", line 25, in load_manifest
    with open(local_filepath) as f:
FileNotFoundError: [Errno 2] No such file or directory: '/usr/local/airflow/dbt/target/manifest.json'
[2022-01-28 07:29:50,604] {processor.py:656} WARNING - No viable dags retrieved from /opt/airflow/dags/dbt_advanced.py
[2022-01-28 07:29:50,613] {processor.py:171} INFO - Processing /opt/airflow/dags/dbt_advanced.py took 0.046 seconds
[2022-01-28 07:30:21,099] {processor.py:163} INFO - Started process (PID=1868) to work on /opt/airflow/dags/dbt_advanced.py
[2022-01-28 07:30:21,101] {processor.py:642} INFO - Processing file /opt/airflow/dags/dbt_advanced.py for tasks to queue
[2022-01-28 07:30:21,102] {logging_mixin.py:109} INFO - [2022-01-28 07:30:21,102] {dagbag.py:500} INFO - Filling up the DagBag from /opt/airflow/dags/dbt_advanced.py
[2022-01-28 07:30:21,114] {logging_mixin.py:109} INFO - [2022-01-28 07:30:21,113] {dagbag.py:334} ERROR - Failed to import: /opt/airflow/dags/dbt_advanced.py
Traceback (most recent call last):
  File "/home/airflow/.local/lib/python3.6/site-packages/airflow/models/dagbag.py", line 331, in _load_modules_from_file
    loader.exec_module(new_module)
  File "<frozen importlib._bootstrap_external>", line 678, in exec_module
  File "<frozen importlib._bootstrap>", line 219, in _call_with_frames_removed
  File "/opt/airflow/dags/dbt_advanced.py", line 64, in <module>
    data = load_manifest()
  File "/opt/airflow/dags/dbt_advanced.py", line 25, in load_manifest
    with open(local_filepath) as f:
FileNotFoundError: [Errno 2] No such file or directory: '/usr/local/airflow/dbt/target/manifest.json'
[2022-01-28 07:30:21,137] {processor.py:656} WARNING - No viable dags retrieved from /opt/airflow/dags/dbt_advanced.py
[2022-01-28 07:30:21,148] {processor.py:171} INFO - Processing /opt/airflow/dags/dbt_advanced.py took 0.054 seconds
[2022-01-28 07:30:51,677] {processor.py:163} INFO - Started process (PID=1937) to work on /opt/airflow/dags/dbt_advanced.py
[2022-01-28 07:30:51,683] {processor.py:642} INFO - Processing file /opt/airflow/dags/dbt_advanced.py for tasks to queue
[2022-01-28 07:30:51,684] {logging_mixin.py:109} INFO - [2022-01-28 07:30:51,684] {dagbag.py:500} INFO - Filling up the DagBag from /opt/airflow/dags/dbt_advanced.py
[2022-01-28 07:30:51,709] {logging_mixin.py:109} INFO - [2022-01-28 07:30:51,708] {dagbag.py:334} ERROR - Failed to import: /opt/airflow/dags/dbt_advanced.py
Traceback (most recent call last):
  File "/home/airflow/.local/lib/python3.6/site-packages/airflow/models/dagbag.py", line 331, in _load_modules_from_file
    loader.exec_module(new_module)
  File "<frozen importlib._bootstrap_external>", line 678, in exec_module
  File "<frozen importlib._bootstrap>", line 219, in _call_with_frames_removed
  File "/opt/airflow/dags/dbt_advanced.py", line 64, in <module>
    data = load_manifest()
  File "/opt/airflow/dags/dbt_advanced.py", line 25, in load_manifest
    with open(local_filepath) as f:
FileNotFoundError: [Errno 2] No such file or directory: '/usr/local/airflow/dbt/target/manifest.json'
[2022-01-28 07:30:51,796] {processor.py:656} WARNING - No viable dags retrieved from /opt/airflow/dags/dbt_advanced.py
[2022-01-28 07:30:51,819] {processor.py:171} INFO - Processing /opt/airflow/dags/dbt_advanced.py took 0.146 seconds
[2022-01-28 07:31:22,289] {processor.py:163} INFO - Started process (PID=1994) to work on /opt/airflow/dags/dbt_advanced.py
[2022-01-28 07:31:22,291] {processor.py:642} INFO - Processing file /opt/airflow/dags/dbt_advanced.py for tasks to queue
[2022-01-28 07:31:22,291] {logging_mixin.py:109} INFO - [2022-01-28 07:31:22,291] {dagbag.py:500} INFO - Filling up the DagBag from /opt/airflow/dags/dbt_advanced.py
[2022-01-28 07:31:22,302] {logging_mixin.py:109} INFO - [2022-01-28 07:31:22,301] {dagbag.py:334} ERROR - Failed to import: /opt/airflow/dags/dbt_advanced.py
Traceback (most recent call last):
  File "/home/airflow/.local/lib/python3.6/site-packages/airflow/models/dagbag.py", line 331, in _load_modules_from_file
    loader.exec_module(new_module)
  File "<frozen importlib._bootstrap_external>", line 678, in exec_module
  File "<frozen importlib._bootstrap>", line 219, in _call_with_frames_removed
  File "/opt/airflow/dags/dbt_advanced.py", line 64, in <module>
    data = load_manifest()
  File "/opt/airflow/dags/dbt_advanced.py", line 25, in load_manifest
    with open(local_filepath) as f:
FileNotFoundError: [Errno 2] No such file or directory: '/usr/local/airflow/dbt/target/manifest.json'
[2022-01-28 07:31:22,321] {processor.py:656} WARNING - No viable dags retrieved from /opt/airflow/dags/dbt_advanced.py
[2022-01-28 07:31:22,330] {processor.py:171} INFO - Processing /opt/airflow/dags/dbt_advanced.py took 0.045 seconds
[2022-01-28 07:31:52,896] {processor.py:163} INFO - Started process (PID=2052) to work on /opt/airflow/dags/dbt_advanced.py
[2022-01-28 07:31:52,897] {processor.py:642} INFO - Processing file /opt/airflow/dags/dbt_advanced.py for tasks to queue
[2022-01-28 07:31:52,898] {logging_mixin.py:109} INFO - [2022-01-28 07:31:52,898] {dagbag.py:500} INFO - Filling up the DagBag from /opt/airflow/dags/dbt_advanced.py
[2022-01-28 07:31:52,907] {logging_mixin.py:109} INFO - [2022-01-28 07:31:52,906] {dagbag.py:334} ERROR - Failed to import: /opt/airflow/dags/dbt_advanced.py
Traceback (most recent call last):
  File "/home/airflow/.local/lib/python3.6/site-packages/airflow/models/dagbag.py", line 331, in _load_modules_from_file
    loader.exec_module(new_module)
  File "<frozen importlib._bootstrap_external>", line 678, in exec_module
  File "<frozen importlib._bootstrap>", line 219, in _call_with_frames_removed
  File "/opt/airflow/dags/dbt_advanced.py", line 64, in <module>
    data = load_manifest()
  File "/opt/airflow/dags/dbt_advanced.py", line 25, in load_manifest
    with open(local_filepath) as f:
FileNotFoundError: [Errno 2] No such file or directory: '/usr/local/airflow/dbt/target/manifest.json'
[2022-01-28 07:31:52,926] {processor.py:656} WARNING - No viable dags retrieved from /opt/airflow/dags/dbt_advanced.py
[2022-01-28 07:31:52,934] {processor.py:171} INFO - Processing /opt/airflow/dags/dbt_advanced.py took 0.043 seconds
[2022-01-28 07:32:23,271] {processor.py:163} INFO - Started process (PID=2120) to work on /opt/airflow/dags/dbt_advanced.py
[2022-01-28 07:32:23,273] {processor.py:642} INFO - Processing file /opt/airflow/dags/dbt_advanced.py for tasks to queue
[2022-01-28 07:32:23,274] {logging_mixin.py:109} INFO - [2022-01-28 07:32:23,274] {dagbag.py:500} INFO - Filling up the DagBag from /opt/airflow/dags/dbt_advanced.py
[2022-01-28 07:32:23,288] {logging_mixin.py:109} INFO - [2022-01-28 07:32:23,286] {dagbag.py:334} ERROR - Failed to import: /opt/airflow/dags/dbt_advanced.py
Traceback (most recent call last):
  File "/home/airflow/.local/lib/python3.6/site-packages/airflow/models/dagbag.py", line 331, in _load_modules_from_file
    loader.exec_module(new_module)
  File "<frozen importlib._bootstrap_external>", line 678, in exec_module
  File "<frozen importlib._bootstrap>", line 219, in _call_with_frames_removed
  File "/opt/airflow/dags/dbt_advanced.py", line 64, in <module>
    data = load_manifest()
  File "/opt/airflow/dags/dbt_advanced.py", line 25, in load_manifest
    with open(local_filepath) as f:
FileNotFoundError: [Errno 2] No such file or directory: '/usr/local/airflow/dbt/target/manifest.json'
[2022-01-28 07:32:23,316] {processor.py:656} WARNING - No viable dags retrieved from /opt/airflow/dags/dbt_advanced.py
[2022-01-28 07:32:23,329] {processor.py:171} INFO - Processing /opt/airflow/dags/dbt_advanced.py took 0.064 seconds
[2022-01-28 07:32:53,568] {processor.py:163} INFO - Started process (PID=2179) to work on /opt/airflow/dags/dbt_advanced.py
[2022-01-28 07:32:53,570] {processor.py:642} INFO - Processing file /opt/airflow/dags/dbt_advanced.py for tasks to queue
[2022-01-28 07:32:53,570] {logging_mixin.py:109} INFO - [2022-01-28 07:32:53,570] {dagbag.py:500} INFO - Filling up the DagBag from /opt/airflow/dags/dbt_advanced.py
[2022-01-28 07:32:53,581] {logging_mixin.py:109} INFO - [2022-01-28 07:32:53,580] {dagbag.py:334} ERROR - Failed to import: /opt/airflow/dags/dbt_advanced.py
Traceback (most recent call last):
  File "/home/airflow/.local/lib/python3.6/site-packages/airflow/models/dagbag.py", line 331, in _load_modules_from_file
    loader.exec_module(new_module)
  File "<frozen importlib._bootstrap_external>", line 678, in exec_module
  File "<frozen importlib._bootstrap>", line 219, in _call_with_frames_removed
  File "/opt/airflow/dags/dbt_advanced.py", line 64, in <module>
    data = load_manifest()
  File "/opt/airflow/dags/dbt_advanced.py", line 25, in load_manifest
    with open(local_filepath) as f:
FileNotFoundError: [Errno 2] No such file or directory: '/usr/local/airflow/dbt/target/manifest.json'
[2022-01-28 07:32:53,600] {processor.py:656} WARNING - No viable dags retrieved from /opt/airflow/dags/dbt_advanced.py
[2022-01-28 07:32:53,610] {processor.py:171} INFO - Processing /opt/airflow/dags/dbt_advanced.py took 0.046 seconds
[2022-01-28 07:33:24,318] {processor.py:163} INFO - Started process (PID=2237) to work on /opt/airflow/dags/dbt_advanced.py
[2022-01-28 07:33:24,319] {processor.py:642} INFO - Processing file /opt/airflow/dags/dbt_advanced.py for tasks to queue
[2022-01-28 07:33:24,320] {logging_mixin.py:109} INFO - [2022-01-28 07:33:24,320] {dagbag.py:500} INFO - Filling up the DagBag from /opt/airflow/dags/dbt_advanced.py
[2022-01-28 07:33:24,330] {logging_mixin.py:109} INFO - [2022-01-28 07:33:24,329] {dagbag.py:334} ERROR - Failed to import: /opt/airflow/dags/dbt_advanced.py
Traceback (most recent call last):
  File "/home/airflow/.local/lib/python3.6/site-packages/airflow/models/dagbag.py", line 331, in _load_modules_from_file
    loader.exec_module(new_module)
  File "<frozen importlib._bootstrap_external>", line 678, in exec_module
  File "<frozen importlib._bootstrap>", line 219, in _call_with_frames_removed
  File "/opt/airflow/dags/dbt_advanced.py", line 64, in <module>
    data = load_manifest()
  File "/opt/airflow/dags/dbt_advanced.py", line 25, in load_manifest
    with open(local_filepath) as f:
FileNotFoundError: [Errno 2] No such file or directory: '/usr/local/airflow/dbt/target/manifest.json'
[2022-01-28 07:33:24,349] {processor.py:656} WARNING - No viable dags retrieved from /opt/airflow/dags/dbt_advanced.py
[2022-01-28 07:33:24,358] {processor.py:171} INFO - Processing /opt/airflow/dags/dbt_advanced.py took 0.045 seconds
[2022-01-28 07:33:54,780] {processor.py:163} INFO - Started process (PID=2295) to work on /opt/airflow/dags/dbt_advanced.py
[2022-01-28 07:33:54,781] {processor.py:642} INFO - Processing file /opt/airflow/dags/dbt_advanced.py for tasks to queue
[2022-01-28 07:33:54,782] {logging_mixin.py:109} INFO - [2022-01-28 07:33:54,782] {dagbag.py:500} INFO - Filling up the DagBag from /opt/airflow/dags/dbt_advanced.py
[2022-01-28 07:33:54,792] {logging_mixin.py:109} INFO - [2022-01-28 07:33:54,792] {dagbag.py:334} ERROR - Failed to import: /opt/airflow/dags/dbt_advanced.py
Traceback (most recent call last):
  File "/home/airflow/.local/lib/python3.6/site-packages/airflow/models/dagbag.py", line 331, in _load_modules_from_file
    loader.exec_module(new_module)
  File "<frozen importlib._bootstrap_external>", line 678, in exec_module
  File "<frozen importlib._bootstrap>", line 219, in _call_with_frames_removed
  File "/opt/airflow/dags/dbt_advanced.py", line 64, in <module>
    data = load_manifest()
  File "/opt/airflow/dags/dbt_advanced.py", line 25, in load_manifest
    with open(local_filepath) as f:
FileNotFoundError: [Errno 2] No such file or directory: '/usr/local/airflow/dbt/target/manifest.json'
[2022-01-28 07:33:54,810] {processor.py:656} WARNING - No viable dags retrieved from /opt/airflow/dags/dbt_advanced.py
[2022-01-28 07:33:54,818] {processor.py:171} INFO - Processing /opt/airflow/dags/dbt_advanced.py took 0.042 seconds
[2022-01-28 07:34:24,915] {processor.py:163} INFO - Started process (PID=2363) to work on /opt/airflow/dags/dbt_advanced.py
[2022-01-28 07:34:24,917] {processor.py:642} INFO - Processing file /opt/airflow/dags/dbt_advanced.py for tasks to queue
[2022-01-28 07:34:24,918] {logging_mixin.py:109} INFO - [2022-01-28 07:34:24,918] {dagbag.py:500} INFO - Filling up the DagBag from /opt/airflow/dags/dbt_advanced.py
[2022-01-28 07:34:24,928] {logging_mixin.py:109} INFO - [2022-01-28 07:34:24,928] {dagbag.py:334} ERROR - Failed to import: /opt/airflow/dags/dbt_advanced.py
Traceback (most recent call last):
  File "/home/airflow/.local/lib/python3.6/site-packages/airflow/models/dagbag.py", line 331, in _load_modules_from_file
    loader.exec_module(new_module)
  File "<frozen importlib._bootstrap_external>", line 678, in exec_module
  File "<frozen importlib._bootstrap>", line 219, in _call_with_frames_removed
  File "/opt/airflow/dags/dbt_advanced.py", line 64, in <module>
    data = load_manifest()
  File "/opt/airflow/dags/dbt_advanced.py", line 25, in load_manifest
    with open(local_filepath) as f:
FileNotFoundError: [Errno 2] No such file or directory: '/usr/local/airflow/dbt/target/manifest.json'
[2022-01-28 07:34:24,959] {processor.py:656} WARNING - No viable dags retrieved from /opt/airflow/dags/dbt_advanced.py
[2022-01-28 07:34:24,967] {processor.py:171} INFO - Processing /opt/airflow/dags/dbt_advanced.py took 0.056 seconds
[2022-01-28 07:34:55,429] {processor.py:163} INFO - Started process (PID=2421) to work on /opt/airflow/dags/dbt_advanced.py
[2022-01-28 07:34:55,431] {processor.py:642} INFO - Processing file /opt/airflow/dags/dbt_advanced.py for tasks to queue
[2022-01-28 07:34:55,431] {logging_mixin.py:109} INFO - [2022-01-28 07:34:55,431] {dagbag.py:500} INFO - Filling up the DagBag from /opt/airflow/dags/dbt_advanced.py
[2022-01-28 07:34:55,444] {logging_mixin.py:109} INFO - [2022-01-28 07:34:55,443] {dagbag.py:334} ERROR - Failed to import: /opt/airflow/dags/dbt_advanced.py
Traceback (most recent call last):
  File "/home/airflow/.local/lib/python3.6/site-packages/airflow/models/dagbag.py", line 331, in _load_modules_from_file
    loader.exec_module(new_module)
  File "<frozen importlib._bootstrap_external>", line 678, in exec_module
  File "<frozen importlib._bootstrap>", line 219, in _call_with_frames_removed
  File "/opt/airflow/dags/dbt_advanced.py", line 64, in <module>
    data = load_manifest()
  File "/opt/airflow/dags/dbt_advanced.py", line 25, in load_manifest
    with open(local_filepath) as f:
FileNotFoundError: [Errno 2] No such file or directory: '/usr/local/airflow/dbt/target/manifest.json'
[2022-01-28 07:34:55,464] {processor.py:656} WARNING - No viable dags retrieved from /opt/airflow/dags/dbt_advanced.py
[2022-01-28 07:34:55,473] {processor.py:171} INFO - Processing /opt/airflow/dags/dbt_advanced.py took 0.048 seconds
