[2022-01-21 10:40:47,799] {taskinstance.py:1032} INFO - Dependencies all met for <TaskInstance: dbt_basic_dag.dbt_seed manual__2022-01-21T10:40:46.571822+00:00 [queued]>
[2022-01-21 10:40:47,812] {taskinstance.py:1032} INFO - Dependencies all met for <TaskInstance: dbt_basic_dag.dbt_seed manual__2022-01-21T10:40:46.571822+00:00 [queued]>
[2022-01-21 10:40:47,812] {taskinstance.py:1238} INFO - 
--------------------------------------------------------------------------------
[2022-01-21 10:40:47,812] {taskinstance.py:1239} INFO - Starting attempt 1 of 1
[2022-01-21 10:40:47,813] {taskinstance.py:1240} INFO - 
--------------------------------------------------------------------------------
[2022-01-21 10:40:47,826] {taskinstance.py:1259} INFO - Executing <Task(BashOperator): dbt_seed> on 2022-01-21 10:40:46.571822+00:00
[2022-01-21 10:40:47,830] {standard_task_runner.py:52} INFO - Started process 10440 to run task
[2022-01-21 10:40:47,837] {standard_task_runner.py:76} INFO - Running: ['***', 'tasks', 'run', 'dbt_basic_dag', 'dbt_seed', 'manual__2022-01-21T10:40:46.571822+00:00', '--job-id', '2', '--raw', '--subdir', 'DAGS_FOLDER/dbt_basic.py', '--cfg-path', '/tmp/tmpcvo97f7x', '--error-file', '/tmp/tmp9a__3ajm']
[2022-01-21 10:40:47,837] {standard_task_runner.py:77} INFO - Job 2: Subtask dbt_seed
[2022-01-21 10:40:47,897] {logging_mixin.py:109} INFO - Running <TaskInstance: dbt_basic_dag.dbt_seed manual__2022-01-21T10:40:46.571822+00:00 [running]> on host c20cfa89904c
[2022-01-21 10:40:47,954] {taskinstance.py:1426} INFO - Exporting the following env vars:
AIRFLOW_CTX_DAG_OWNER=astronomer
AIRFLOW_CTX_DAG_ID=dbt_basic_dag
AIRFLOW_CTX_TASK_ID=dbt_seed
AIRFLOW_CTX_EXECUTION_DATE=2022-01-21T10:40:46.571822+00:00
AIRFLOW_CTX_DAG_RUN_ID=manual__2022-01-21T10:40:46.571822+00:00
[2022-01-21 10:40:47,956] {subprocess.py:62} INFO - Tmp dir root location: 
 /tmp
[2022-01-21 10:40:47,956] {subprocess.py:74} INFO - Running command: ['bash', '-c', 'dbt seed --profiles-dir /home/***/.dbt --project-dir /usr/local/***/dbt']
[2022-01-21 10:40:47,970] {subprocess.py:85} INFO - Output:
[2022-01-21 10:40:51,111] {subprocess.py:89} INFO - Running with dbt=0.21.1
[2022-01-21 10:40:51,111] {subprocess.py:89} INFO - Encountered an error:
[2022-01-21 10:40:51,111] {subprocess.py:89} INFO - Runtime Error
[2022-01-21 10:40:51,111] {subprocess.py:89} INFO -   fatal: Invalid --project-dir flag. Not a dbt project. Missing dbt_project.yml file
[2022-01-21 10:40:51,325] {subprocess.py:93} INFO - Command exited with return code 2
[2022-01-21 10:40:51,342] {taskinstance.py:1700} ERROR - Task failed with exception
Traceback (most recent call last):
  File "/home/airflow/.local/lib/python3.6/site-packages/airflow/models/taskinstance.py", line 1329, in _run_raw_task
    self._execute_task_with_callbacks(context)
  File "/home/airflow/.local/lib/python3.6/site-packages/airflow/models/taskinstance.py", line 1455, in _execute_task_with_callbacks
    result = self._execute_task(context, self.task)
  File "/home/airflow/.local/lib/python3.6/site-packages/airflow/models/taskinstance.py", line 1511, in _execute_task
    result = execute_callable(context=context)
  File "/home/airflow/.local/lib/python3.6/site-packages/airflow/operators/bash.py", line 188, in execute
    f'Bash command failed. The command returned a non-zero exit code {result.exit_code}.'
airflow.exceptions.AirflowException: Bash command failed. The command returned a non-zero exit code 2.
[2022-01-21 10:40:51,348] {taskinstance.py:1277} INFO - Marking task as FAILED. dag_id=dbt_basic_dag, task_id=dbt_seed, execution_date=20220121T104046, start_date=20220121T104047, end_date=20220121T104051
[2022-01-21 10:40:51,363] {standard_task_runner.py:92} ERROR - Failed to execute job 2 for task dbt_seed
Traceback (most recent call last):
  File "/home/airflow/.local/lib/python3.6/site-packages/airflow/task/task_runner/standard_task_runner.py", line 85, in _start_by_fork
    args.func(args, dag=self.dag)
  File "/home/airflow/.local/lib/python3.6/site-packages/airflow/cli/cli_parser.py", line 48, in command
    return func(*args, **kwargs)
  File "/home/airflow/.local/lib/python3.6/site-packages/airflow/utils/cli.py", line 92, in wrapper
    return f(*args, **kwargs)
  File "/home/airflow/.local/lib/python3.6/site-packages/airflow/cli/commands/task_command.py", line 298, in task_run
    _run_task_by_selected_method(args, dag, ti)
  File "/home/airflow/.local/lib/python3.6/site-packages/airflow/cli/commands/task_command.py", line 107, in _run_task_by_selected_method
    _run_raw_task(args, ti)
  File "/home/airflow/.local/lib/python3.6/site-packages/airflow/cli/commands/task_command.py", line 184, in _run_raw_task
    error_file=args.error_file,
  File "/home/airflow/.local/lib/python3.6/site-packages/airflow/utils/session.py", line 70, in wrapper
    return func(*args, session=session, **kwargs)
  File "/home/airflow/.local/lib/python3.6/site-packages/airflow/models/taskinstance.py", line 1329, in _run_raw_task
    self._execute_task_with_callbacks(context)
  File "/home/airflow/.local/lib/python3.6/site-packages/airflow/models/taskinstance.py", line 1455, in _execute_task_with_callbacks
    result = self._execute_task(context, self.task)
  File "/home/airflow/.local/lib/python3.6/site-packages/airflow/models/taskinstance.py", line 1511, in _execute_task
    result = execute_callable(context=context)
  File "/home/airflow/.local/lib/python3.6/site-packages/airflow/operators/bash.py", line 188, in execute
    f'Bash command failed. The command returned a non-zero exit code {result.exit_code}.'
airflow.exceptions.AirflowException: Bash command failed. The command returned a non-zero exit code 2.
[2022-01-21 10:40:51,372] {local_task_job.py:154} INFO - Task exited with return code 1
[2022-01-21 10:40:51,414] {local_task_job.py:264} INFO - 0 downstream tasks scheduled from follow-on schedule check
